[2023-07-26T14:35:19.325+0000] {taskinstance.py:1103} INFO - Dependencies all met for dep_context=non-requeueable deps ti=<TaskInstance: dag_with_postgresv01.get_s3_id scheduled__2023-07-25T00:00:00+00:00 [queued]>
[2023-07-26T14:35:19.331+0000] {taskinstance.py:1103} INFO - Dependencies all met for dep_context=requeueable deps ti=<TaskInstance: dag_with_postgresv01.get_s3_id scheduled__2023-07-25T00:00:00+00:00 [queued]>
[2023-07-26T14:35:19.331+0000] {taskinstance.py:1308} INFO - Starting attempt 4 of 9
[2023-07-26T14:35:19.339+0000] {taskinstance.py:1327} INFO - Executing <Task(S3KeySensor): get_s3_id> on 2023-07-25 00:00:00+00:00
[2023-07-26T14:35:19.343+0000] {standard_task_runner.py:57} INFO - Started process 1826 to run task
[2023-07-26T14:35:19.345+0000] {standard_task_runner.py:84} INFO - Running: ['airflow', 'tasks', 'run', 'dag_with_postgresv01', 'get_s3_id', 'scheduled__2023-07-25T00:00:00+00:00', '--job-id', '6', '--raw', '--subdir', 'DAGS_FOLDER/dag_with_dependency.py', '--cfg-path', '/tmp/tmpklbddjjf']
[2023-07-26T14:35:19.347+0000] {standard_task_runner.py:85} INFO - Job 6: Subtask get_s3_id
[2023-07-26T14:35:19.386+0000] {task_command.py:410} INFO - Running <TaskInstance: dag_with_postgresv01.get_s3_id scheduled__2023-07-25T00:00:00+00:00 [running]> on host 93edf6c77c0f
[2023-07-26T14:35:19.444+0000] {taskinstance.py:1547} INFO - Exporting env vars: AIRFLOW_CTX_DAG_OWNER='richy' AIRFLOW_CTX_DAG_ID='dag_with_postgresv01' AIRFLOW_CTX_TASK_ID='get_s3_id' AIRFLOW_CTX_EXECUTION_DATE='2023-07-25T00:00:00+00:00' AIRFLOW_CTX_TRY_NUMBER='4' AIRFLOW_CTX_DAG_RUN_ID='scheduled__2023-07-25T00:00:00+00:00'
[2023-07-26T14:35:19.449+0000] {s3.py:99} INFO - Poking for key : s3://minikubebucket/iris-dataset.csv
[2023-07-26T14:35:19.460+0000] {base.py:73} INFO - Using connection ID 'aws_conn' for task execution.
[2023-07-26T14:35:19.461+0000] {connection_wrapper.py:337} INFO - AWS Connection (conn_id='aws_conn', conn_type='aws') credentials retrieved from login and password.
[2023-07-26T14:35:19.743+0000] {taskinstance.py:1824} ERROR - Task failed with exception
Traceback (most recent call last):
  File "/home/airflow/.local/lib/python3.7/site-packages/airflow/sensors/base.py", line 225, in execute
    raise e
  File "/home/airflow/.local/lib/python3.7/site-packages/airflow/sensors/base.py", line 212, in execute
    poke_return = self.poke(context)
  File "/home/airflow/.local/lib/python3.7/site-packages/airflow/providers/amazon/aws/sensors/s3.py", line 130, in poke
    return self._check_key(self.bucket_key)
  File "/home/airflow/.local/lib/python3.7/site-packages/airflow/providers/amazon/aws/sensors/s3.py", line 118, in _check_key
    obj = self.hook.head_object(key, bucket_name)
  File "/home/airflow/.local/lib/python3.7/site-packages/airflow/providers/amazon/aws/hooks/s3.py", line 115, in wrapper
    return func(*bound_args.args, **bound_args.kwargs)
  File "/home/airflow/.local/lib/python3.7/site-packages/airflow/providers/amazon/aws/hooks/s3.py", line 86, in wrapper
    return func(*bound_args.args, **bound_args.kwargs)
  File "/home/airflow/.local/lib/python3.7/site-packages/airflow/providers/amazon/aws/hooks/s3.py", line 508, in head_object
    raise e
  File "/home/airflow/.local/lib/python3.7/site-packages/airflow/providers/amazon/aws/hooks/s3.py", line 503, in head_object
    return self.get_conn().head_object(Bucket=bucket_name, Key=key)
  File "/home/airflow/.local/lib/python3.7/site-packages/botocore/client.py", line 530, in _api_call
    return self._make_api_call(operation_name, kwargs)
  File "/home/airflow/.local/lib/python3.7/site-packages/botocore/client.py", line 964, in _make_api_call
    raise error_class(parsed_response, operation_name)
botocore.exceptions.ClientError: An error occurred (403) when calling the HeadObject operation: Forbidden
[2023-07-26T14:35:19.750+0000] {taskinstance.py:1350} INFO - Marking task as UP_FOR_RETRY. dag_id=dag_with_postgresv01, task_id=get_s3_id, execution_date=20230725T000000, start_date=20230726T143519, end_date=20230726T143519
[2023-07-26T14:35:19.757+0000] {standard_task_runner.py:109} ERROR - Failed to execute job 6 for task get_s3_id (An error occurred (403) when calling the HeadObject operation: Forbidden; 1826)
[2023-07-26T14:35:19.806+0000] {local_task_job_runner.py:225} INFO - Task exited with return code 1
[2023-07-26T14:35:19.820+0000] {taskinstance.py:2653} INFO - 0 downstream tasks scheduled from follow-on schedule check
