[2023-07-26T14:28:45.916+0000] {taskinstance.py:1103} INFO - Dependencies all met for dep_context=non-requeueable deps ti=<TaskInstance: dag_with_postgresv01.get_s3_id scheduled__2023-07-25T00:00:00+00:00 [queued]>
[2023-07-26T14:28:45.924+0000] {taskinstance.py:1103} INFO - Dependencies all met for dep_context=requeueable deps ti=<TaskInstance: dag_with_postgresv01.get_s3_id scheduled__2023-07-25T00:00:00+00:00 [queued]>
[2023-07-26T14:28:45.925+0000] {taskinstance.py:1308} INFO - Starting attempt 2 of 7
[2023-07-26T14:28:45.935+0000] {taskinstance.py:1327} INFO - Executing <Task(S3KeySensor): get_s3_id> on 2023-07-25 00:00:00+00:00
[2023-07-26T14:28:45.938+0000] {standard_task_runner.py:57} INFO - Started process 1536 to run task
[2023-07-26T14:28:45.941+0000] {standard_task_runner.py:84} INFO - Running: ['airflow', 'tasks', 'run', 'dag_with_postgresv01', 'get_s3_id', 'scheduled__2023-07-25T00:00:00+00:00', '--job-id', '4', '--raw', '--subdir', 'DAGS_FOLDER/dag_with_dependency.py', '--cfg-path', '/tmp/tmpuo4p_0v7']
[2023-07-26T14:28:45.943+0000] {standard_task_runner.py:85} INFO - Job 4: Subtask get_s3_id
[2023-07-26T14:28:45.984+0000] {task_command.py:410} INFO - Running <TaskInstance: dag_with_postgresv01.get_s3_id scheduled__2023-07-25T00:00:00+00:00 [running]> on host 93edf6c77c0f
[2023-07-26T14:28:46.044+0000] {taskinstance.py:1547} INFO - Exporting env vars: AIRFLOW_CTX_DAG_OWNER='richy' AIRFLOW_CTX_DAG_ID='dag_with_postgresv01' AIRFLOW_CTX_TASK_ID='get_s3_id' AIRFLOW_CTX_EXECUTION_DATE='2023-07-25T00:00:00+00:00' AIRFLOW_CTX_TRY_NUMBER='2' AIRFLOW_CTX_DAG_RUN_ID='scheduled__2023-07-25T00:00:00+00:00'
[2023-07-26T14:28:46.045+0000] {s3.py:99} INFO - Poking for key : s3://minikubebucket/iris-dataset.csv
[2023-07-26T14:28:46.056+0000] {base_aws.py:551} WARNING - Unable to find AWS Connection ID 'aws_conn', switching to empty.
[2023-07-26T14:28:46.057+0000] {base_aws.py:160} INFO - No connection ID provided. Fallback on boto3 credential strategy (region_name=None). See: https://boto3.amazonaws.com/v1/documentation/api/latest/guide/configuration.html
[2023-07-26T14:28:46.327+0000] {taskinstance.py:1824} ERROR - Task failed with exception
Traceback (most recent call last):
  File "/home/airflow/.local/lib/python3.7/site-packages/airflow/sensors/base.py", line 225, in execute
    raise e
  File "/home/airflow/.local/lib/python3.7/site-packages/airflow/sensors/base.py", line 212, in execute
    poke_return = self.poke(context)
  File "/home/airflow/.local/lib/python3.7/site-packages/airflow/providers/amazon/aws/sensors/s3.py", line 130, in poke
    return self._check_key(self.bucket_key)
  File "/home/airflow/.local/lib/python3.7/site-packages/airflow/providers/amazon/aws/sensors/s3.py", line 118, in _check_key
    obj = self.hook.head_object(key, bucket_name)
  File "/home/airflow/.local/lib/python3.7/site-packages/airflow/providers/amazon/aws/hooks/s3.py", line 115, in wrapper
    return func(*bound_args.args, **bound_args.kwargs)
  File "/home/airflow/.local/lib/python3.7/site-packages/airflow/providers/amazon/aws/hooks/s3.py", line 86, in wrapper
    return func(*bound_args.args, **bound_args.kwargs)
  File "/home/airflow/.local/lib/python3.7/site-packages/airflow/providers/amazon/aws/hooks/s3.py", line 503, in head_object
    return self.get_conn().head_object(Bucket=bucket_name, Key=key)
  File "/home/airflow/.local/lib/python3.7/site-packages/botocore/client.py", line 530, in _api_call
    return self._make_api_call(operation_name, kwargs)
  File "/home/airflow/.local/lib/python3.7/site-packages/botocore/client.py", line 948, in _make_api_call
    operation_model, request_dict, request_context
  File "/home/airflow/.local/lib/python3.7/site-packages/botocore/client.py", line 970, in _make_request
    return self._endpoint.make_request(operation_model, request_dict)
  File "/home/airflow/.local/lib/python3.7/site-packages/botocore/endpoint.py", line 119, in make_request
    return self._send_request(request_dict, operation_model)
  File "/home/airflow/.local/lib/python3.7/site-packages/botocore/endpoint.py", line 198, in _send_request
    request = self.create_request(request_dict, operation_model)
  File "/home/airflow/.local/lib/python3.7/site-packages/botocore/endpoint.py", line 137, in create_request
    operation_name=operation_model.name,
  File "/home/airflow/.local/lib/python3.7/site-packages/botocore/hooks.py", line 412, in emit
    return self._emitter.emit(aliased_event_name, **kwargs)
  File "/home/airflow/.local/lib/python3.7/site-packages/botocore/hooks.py", line 256, in emit
    return self._emit(event_name, kwargs)
  File "/home/airflow/.local/lib/python3.7/site-packages/botocore/hooks.py", line 239, in _emit
    response = handler(**kwargs)
  File "/home/airflow/.local/lib/python3.7/site-packages/botocore/signers.py", line 105, in handler
    return self.sign(operation_name, request)
  File "/home/airflow/.local/lib/python3.7/site-packages/botocore/signers.py", line 189, in sign
    auth.add_auth(request)
  File "/home/airflow/.local/lib/python3.7/site-packages/botocore/auth.py", line 418, in add_auth
    raise NoCredentialsError()
botocore.exceptions.NoCredentialsError: Unable to locate credentials
[2023-07-26T14:28:46.336+0000] {taskinstance.py:1350} INFO - Marking task as UP_FOR_RETRY. dag_id=dag_with_postgresv01, task_id=get_s3_id, execution_date=20230725T000000, start_date=20230726T142845, end_date=20230726T142846
[2023-07-26T14:28:46.342+0000] {standard_task_runner.py:109} ERROR - Failed to execute job 4 for task get_s3_id (Unable to locate credentials; 1536)
[2023-07-26T14:28:46.404+0000] {local_task_job_runner.py:225} INFO - Task exited with return code 1
[2023-07-26T14:28:46.418+0000] {taskinstance.py:2653} INFO - 0 downstream tasks scheduled from follow-on schedule check
